WARNING: yacc table file version is out of date
[2019-03-08 10:45:18,335: INFO/MainProcess] Connected to redis+socket:///var/run/redis/redis.sock
[2019-03-08 10:45:18,341: INFO/MainProcess] mingle: searching for neighbors
[2019-03-08 10:45:19,346: INFO/MainProcess] mingle: all alone
[2019-03-08 10:45:19,355: WARNING/MainProcess] celery@d42_queued ready.
[2019-03-08 10:46:02,150: INFO/MainProcess] Received task: rackraj.tasks.QueuedJobRun[bc8fb28a-3e40-4fca-9dea-47545fe559b5]
[2019-03-08 10:46:03,796: INFO/MainProcess] Task rackraj.tasks.QueuedJobRun[bc8fb28a-3e40-4fca-9dea-47545fe559b5] succeeded in 1.642797197s: None
[2019-03-08 10:47:02,061: INFO/MainProcess] Received task: rackraj.tasks.QueuedJobRun[65dc9b30-5356-46cb-870b-f7eb844ee990]
[2019-03-08 10:47:07,609: INFO/MainProcess] Task rackraj.tasks.QueuedJobRun[65dc9b30-5356-46cb-870b-f7eb844ee990] succeeded in 5.543923389s: None
[2019-03-08 10:48:02,066: INFO/MainProcess] Received task: rackraj.tasks.QueuedJobRun[21f15cbc-a85d-41c1-a5db-aedbde534052]
[2019-03-08 10:48:11,188: INFO/MainProcess] Task rackraj.tasks.QueuedJobRun[21f15cbc-a85d-41c1-a5db-aedbde534052] succeeded in 9.118636353s: None
[2019-03-08 10:49:02,090: INFO/MainProcess] Received task: rackraj.tasks.QueuedJobRun[5051cb10-867e-4b6c-a818-4f3802338086]
[2019-03-08 10:49:10,187: INFO/MainProcess] Task rackraj.tasks.QueuedJobRun[5051cb10-867e-4b6c-a818-4f3802338086] succeeded in 8.094037823s: None
[2019-03-08 10:50:02,081: INFO/MainProcess] Received task: rackraj.tasks.QueuedJobRun[3832e3bd-1520-4602-bb84-1782c4585b79]
[2019-03-08 10:50:11,460: INFO/MainProcess] Task rackraj.tasks.QueuedJobRun[3832e3bd-1520-4602-bb84-1782c4585b79] succeeded in 9.375010099s: None
[2019-03-08 10:51:02,076: INFO/MainProcess] Received task: rackraj.tasks.QueuedJobRun[a85c6f28-ff36-4867-b162-2fc074492d4f]
[2019-03-08 10:51:13,571: WARNING/Worker-3] /usr/lib/python2.7/site-packages/django/db/models/fields/__init__.py:808: RuntimeWarning: DateTimeField received a naive datetime (2019-03-08 10:51:03.133297) while time zone support is active.
  RuntimeWarning)
[2019-03-08 10:51:14,585: WARNING/Worker-3] /usr/lib/python2.7/site-packages/django/db/models/fields/__init__.py:808: RuntimeWarning: DateTimeField received a naive datetime (2019-03-08 10:51:14.031025) while time zone support is active.
  RuntimeWarning)
[2019-03-08 10:51:15,141: WARNING/Worker-3] /usr/lib/python2.7/site-packages/django/db/models/fields/__init__.py:808: RuntimeWarning: DateTimeField received a naive datetime (2019-03-08 10:51:14.679781) while time zone support is active.
  RuntimeWarning)
[2019-03-08 10:51:15,355: WARNING/Worker-3] /usr/lib/python2.7/site-packages/django/db/models/fields/__init__.py:808: RuntimeWarning: DateTimeField received a naive datetime (2019-03-08 10:51:15.248014) while time zone support is active.
  RuntimeWarning)
[2019-03-08 10:51:17,719: WARNING/Worker-3] /usr/lib/python2.7/site-packages/django/db/models/fields/__init__.py:808: RuntimeWarning: DateTimeField received a naive datetime (2019-03-08 10:51:15.408525) while time zone support is active.
  RuntimeWarning)
  RuntimeWarning)
[2019-03-08 10:51:53,829: WARNING/Worker-3] /usr/lib/python2.7/site-packages/django/db/models/fields/__init__.py:808: RuntimeWarning: DateTimeField received a naive datetime (2019-03-08 10:51:53.827213) while time zone support is active.
  RuntimeWarning)
[2019-03-08 10:51:53,855: WARNING/Worker-3] /usr/lib/python2.7/site-packages/django/db/models/fields/__init__.py:808: RuntimeWarning: DateTimeField received a naive datetime (2019-03-08 10:51:53.852770) while time zone support is active.
  RuntimeWarning)
[2019-03-08 10:51:53,884: WARNING/Worker-3] /usr/lib/python2.7/site-packages/django/db/models/fields/__init__.py:808: RuntimeWarning: DateTimeField received a naive datetime (2019-03-08 10:51:53.882348) while time zone support is active.
  RuntimeWarning)
[2019-03-08 10:51:53,910: WARNING/Worker-3] /usr/lib/python2.7/site-packages/django/db/models/fields/__init__.py:808: RuntimeWarning: DateTimeField received a naive datetime (2019-03-08 10:51:53.907979) while time zone support is active.
  RuntimeWarning)
[2019-03-08 10:51:58,548: WARNING/Worker-3] /usr/lib/python2.7/site-packages/django/db/models/fields/__init__.py:808: RuntimeWarning: DateTimeField received a naive datetime (2019-03-08 10:51:50.867671) while time zone support is active.
  RuntimeWarning)
[2019-03-08 10:52:02,097: INFO/MainProcess] Received task: rackraj.tasks.QueuedJobRun[ff7dd4bf-2e76-4960-8e15-da4b08ce36c1]
[2019-03-08 10:52:02,394: WARNING/Worker-26] OptiModel full clean - default to full clean
[2019-03-08 10:52:02,394: WARNING/Worker-26] Traceback (most recent call last):
[2019-03-08 10:52:02,394: WARNING/Worker-26] File "/home/device42/device42-new/device42/d42django/OptiModel.py", line 75, in opt_full_clean
[2019-03-08 10:52:02,394: WARNING/Worker-26] File "/usr/lib/python2.7/site-packages/django/db/models/base.py", line 824, in full_clean
[2019-03-08 10:52:02,395: WARNING/Worker-26] raise ValidationError(errors)
[2019-03-08 10:52:02,395: WARNING/Worker-26] ValidationError: {'__all__': [u'this port and device combination already exists']}
[2019-03-08 10:52:02,395: WARNING/Worker-26] failure in process_device_bulk_data for
[2019-03-08 10:52:02,395: WARNING/Worker-26] {u'macaddress': u'EC:F4:BB:C7:D6:28', u'port_name': u'Intel(R) Ethernet 10G 4P X540/I350 rNDC_d42', 'device_id': 5112}
[2019-03-08 10:52:02,395: WARNING/Worker-26] {'__all__': [u'this port and device combination already exists']}
[2019-03-08 10:52:02,395: WARNING/Worker-26] failure in process_device_bulk_data
[2019-03-08 10:52:02,395: WARNING/Worker-26] Traceback (most recent call last):
[2019-03-08 10:52:02,395: WARNING/Worker-26] File "/home/device42/device42-new/device42/rackraj/CustomFunctions.py", line 12552, in process_device_bulk_data
[2019-03-08 10:52:02,396: WARNING/Worker-26] File "/home/device42/device42-new/device42/rackraj/CustomFunctions.py", line 5136, in mactable_post_api
[2019-03-08 10:52:02,396: WARNING/Worker-26] File "/home/device42/device42-new/device42/d42django/OptiModel.py", line 87, in full_clean
[2019-03-08 10:52:02,396: WARNING/Worker-26] File "/home/device42/device42-new/device42/d42django/OptiModel.py", line 75, in opt_full_clean
[2019-03-08 10:52:02,396: WARNING/Worker-26] File "/usr/lib/python2.7/site-packages/django/db/models/base.py", line 824, in full_clean
[2019-03-08 10:52:02,396: WARNING/Worker-26] raise ValidationError(errors)
[2019-03-08 10:52:02,396: WARNING/Worker-26] ValidationError: {'__all__': [u'this port and device combination already exists']}
[2019-03-08 10:52:02,640: WARNING/Worker-26] /usr/lib/python2.7/site-packages/django/db/models/fields/__init__.py:808: RuntimeWarning: DateTimeField received a naive datetime (2019-03-08 10:52:02.637428) while time zone support is active.
  RuntimeWarning)
[2019-03-08 10:52:07,574: WARNING/Worker-26] /usr/lib/python2.7/site-packages/django/db/models/fields/__init__.py:808: RuntimeWarning: DateTimeField received a naive datetime (2019-03-08 10:52:02.223441) while time zone support is active.
  RuntimeWarning)
[2019-03-08 10:52:07,641: WARNING/Worker-3] /usr/lib/python2.7/site-packages/django/db/models/fields/__init__.py:808: RuntimeWarning: DateTimeField received a naive datetime (2019-03-08 10:51:58.620290) while time zone support is active.
  RuntimeWarning)
[2019-03-08 10:52:08,013: WARNING/Worker-3] /usr/lib/python2.7/site-packages/django/db/models/fields/__init__.py:808: RuntimeWarning: DateTimeField received a naive datetime (2019-03-08 10:52:08.011284) while time zone support is active.
  RuntimeWarning)
[2019-03-08 10:52:08,094: WARNING/Worker-26] /usr/lib/python2.7/site-packages/django/db/models/fields/__init__.py:808: RuntimeWarning: DateTimeField received a naive datetime (2019-03-08 10:52:08.092282) while time zone support is active.
  RuntimeWarning)
[2019-03-08 10:52:08,129: WARNING/Worker-26] /usr/lib/python2.7/site-packages/django/db/models/fields/__init__.py:808: RuntimeWarning: DateTimeField received a naive datetime (2019-03-08 10:52:08.127024) while time zone support is active.
  RuntimeWarning)
[2019-03-08 10:52:08,165: WARNING/Worker-26] /usr/lib/python2.7/site-packages/django/db/models/fields/__init__.py:808: RuntimeWarning: DateTimeField received a naive datetime (2019-03-08 10:52:08.162448) while time zone support is active.
  RuntimeWarning)
[2019-03-08 10:52:08,196: WARNING/Worker-26] /usr/lib/python2.7/site-packages/django/db/models/fields/__init__.py:808: RuntimeWarning: DateTimeField received a naive datetime (2019-03-08 10:52:08.194105) while time zone support is active.
  RuntimeWarning)
[2019-03-08 10:52:08,228: WARNING/Worker-26] /usr/lib/python2.7/site-packages/django/db/models/fields/__init__.py:808: RuntimeWarning: DateTimeField received a naive datetime (2019-03-08 10:52:08.225731) while time zone support is active.
  RuntimeWarning)
[2019-03-08 10:52:10,897: WARNING/Worker-26] /usr/lib/python2.7/site-packages/django/db/models/fields/__init__.py:808: RuntimeWarning: DateTimeField received a naive datetime (2019-03-08 10:52:10.895833) while time zone support is active.
  RuntimeWarning)
[2019-03-08 10:52:10,924: WARNING/Worker-26] /usr/lib/python2.7/site-packages/django/db/models/fields/__init__.py:808: RuntimeWarning: DateTimeField received a naive datetime (2019-03-08 10:52:10.922687) while time zone support is active.
  RuntimeWarning)
[2019-03-08 10:52:10,952: WARNING/Worker-26] /usr/lib/python2.7/site-packages/django/db/models/fields/__init__.py:808: RuntimeWarning: DateTimeField received a naive datetime (2019-03-08 10:52:10.949868) while time zone support is active.
  RuntimeWarning)
[2019-03-08 10:52:11,711: WARNING/Worker-3] /usr/lib/python2.7/site-packages/django/db/models/fields/__init__.py:808: RuntimeWarning: DateTimeField received a naive datetime (2019-03-08 10:52:07.710330) while time zone support is active.
  RuntimeWarning)
[2019-03-08 10:52:11,894: WARNING/Worker-3] failure in process_device_bulk_data for
[2019-03-08 10:52:11,894: WARNING/Worker-3] {u'macaddress': u'EC:F4:BB:C9:1B:D8', u'port_name': u'Intel(R) Ethernet 10G 4P X540/I350 rNDC_d42', 'device_id': 5112}
[2019-03-08 10:52:11,894: WARNING/Worker-3] Another port with different mac exists.
[2019-03-08 10:52:11,894: WARNING/Worker-3] failure in process_device_bulk_data
[2019-03-08 10:52:11,894: WARNING/Worker-3] Traceback (most recent call last):
[2019-03-08 10:52:11,894: WARNING/Worker-3] File "/home/device42/device42-new/device42/rackraj/CustomFunctions.py", line 12552, in process_device_bulk_data
[2019-03-08 10:52:11,895: WARNING/Worker-3] File "/home/device42/device42-new/device42/rackraj/CustomFunctions.py", line 5091, in mactable_post_api
[2019-03-08 10:52:11,895: WARNING/Worker-3] AppError: Another port with different mac exists.
[2019-03-08 10:52:12,056: WARNING/Worker-3] /usr/lib/python2.7/site-packages/django/db/models/fields/__init__.py:808: RuntimeWarning: DateTimeField received a naive datetime (2019-03-08 10:52:12.053977) while time zone support is active.
  RuntimeWarning)
[2019-03-08 10:52:15,635: WARNING/Worker-26] /usr/lib/python2.7/site-packages/django/db/models/fields/__init__.py:808: RuntimeWarning: DateTimeField received a naive datetime (2019-03-08 10:52:07.675233) while time zone support is active.
  RuntimeWarning)
  RuntimeWarning)
[2019-03-08 10:52:52,414: WARNING/Worker-26] /usr/lib/python2.7/site-packages/django/db/models/fields/__init__.py:808: RuntimeWarning: DateTimeField received a naive datetime (2019-03-08 10:52:42.712319) while time zone support is active.
  RuntimeWarning)
[2019-03-08 10:52:52,811: WARNING/Worker-26] /usr/lib/python2.7/site-packages/django/db/models/fields/__init__.py:808: RuntimeWarning: DateTimeField received a naive datetime (2019-03-08 10:52:52.809303) while time zone support is active.
  RuntimeWarning)
[2019-03-08 10:52:55,999: WARNING/Worker-3] /usr/lib/python2.7/site-packages/django/db/models/fields/__init__.py:808: RuntimeWarning: DateTimeField received a naive datetime (2019-03-08 10:52:46.722548) while time zone support is active.
  RuntimeWarning)
[2019-03-08 10:52:56,376: WARNING/Worker-3] /usr/lib/python2.7/site-packages/django/db/models/fields/__init__.py:808: RuntimeWarning: DateTimeField received a naive datetime (2019-03-08 10:52:56.374028) while time zone support is active.
  RuntimeWarning)
[2019-03-08 10:52:57,785: WARNING/Worker-26] /usr/lib/python2.7/site-packages/django/db/models/fields/__init__.py:808: RuntimeWarning: DateTimeField received a naive datetime (2019-03-08 10:52:52.473436) while time zone support is active.
  RuntimeWarning)
[2019-03-08 10:52:59,666: WARNING/Worker-3] /usr/lib/python2.7/site-packages/django/db/models/fields/__init__.py:808: RuntimeWarning: DateTimeField received a naive datetime (2019-03-08 10:52:56.132070) while time zone support is active.
  RuntimeWarning)
[2019-03-08 10:52:59,861: WARNING/Worker-3] OptiModel full clean - default to full clean
[2019-03-08 10:52:59,861: WARNING/Worker-3] Traceback (most recent call last):
[2019-03-08 10:52:59,861: WARNING/Worker-3] File "/home/device42/device42-new/device42/d42django/OptiModel.py", line 75, in opt_full_clean
[2019-03-08 10:52:59,861: WARNING/Worker-3] File "/usr/lib/python2.7/site-packages/django/db/models/base.py", line 824, in full_clean
[2019-03-08 10:52:59,862: WARNING/Worker-3] raise ValidationError(errors)
[2019-03-08 10:52:59,862: WARNING/Worker-3] ValidationError: {'__all__': [u'Object with same name already exists.']}
[2019-03-08 10:52:59,862: WARNING/Worker-3] failure in process_device_bulk_data for
[2019-03-08 10:52:59,862: WARNING/Worker-3] {u'macaddress': u'1C:40:24:7C:3E:A9', u'port_name': u'QLogic BCM57810 10 Gigabit Ethernet (NDIS VBD Client)_NNN', 'device_id': 512}
[2019-03-08 10:52:59,863: WARNING/Worker-3] {'__all__': [u'Object with same name already exists.']}
[2019-03-08 10:52:59,863: WARNING/Worker-3] failure in process_device_bulk_data
[2019-03-08 10:52:59,863: WARNING/Worker-3] Traceback (most recent call last):
[2019-03-08 10:52:59,863: WARNING/Worker-3] File "/home/device42/device42-new/device42/rackraj/CustomFunctions.py", line 12552, in process_device_bulk_data
[2019-03-08 10:52:59,863: WARNING/Worker-3] File "/home/device42/device42-new/device42/rackraj/CustomFunctions.py", line 5136, in mactable_post_api
[2019-03-08 10:52:59,863: WARNING/Worker-3] File "/home/device42/device42-new/device42/d42django/OptiModel.py", line 87, in full_clean
[2019-03-08 10:52:59,863: WARNING/Worker-3] File "/home/device42/device42-new/device42/d42django/OptiModel.py", line 75, in opt_full_clean
[2019-03-08 10:52:59,863: WARNING/Worker-3] File "/usr/lib/python2.7/site-packages/django/db/models/base.py", line 824, in full_clean
[2019-03-08 10:52:59,863: WARNING/Worker-3] raise ValidationError(errors)
[2019-03-08 10:52:59,863: WARNING/Worker-3] ValidationError: {'__all__': [u'Object with same name already exists.']}
[2019-03-08 10:52:59,892: WARNING/Worker-3] failure in process_device_bulk_data for
[2019-03-08 10:52:59,893: WARNING/Worker-3] {u'macaddress': u'02:61:78:14:FA:02', u'port_name': u'Microsoft Failover Cluster Virtual Adapter', 'device_id': 512}
[2019-03-08 10:52:59,893: WARNING/Worker-3] Another port with different mac exists.
[2019-03-08 10:52:59,893: WARNING/Worker-3] failure in process_device_bulk_data
[2019-03-08 10:52:59,893: WARNING/Worker-3] Traceback (most recent call last):
[2019-03-08 10:52:59,893: WARNING/Worker-3] File "/home/device42/device42-new/device42/rackraj/CustomFunctions.py", line 12552, in process_device_bulk_data
[2019-03-08 10:52:59,893: WARNING/Worker-3] File "/home/device42/device42-new/device42/rackraj/CustomFunctions.py", line 5091, in mactable_post_api
[2019-03-08 10:52:59,893: WARNING/Worker-3] AppError: Another port with different mac exists.
[2019-03-08 10:53:00,011: WARNING/Worker-3] /usr/lib/python2.7/site-packages/django/db/models/fields/__init__.py:808: RuntimeWarning: DateTimeField received a naive datetime (2019-03-08 10:53:00.009229) while time zone support is active.
  RuntimeWarning)
[2019-03-08 10:53:01,879: WARNING/Worker-26] /usr/lib/python2.7/site-packages/django/db/models/fields/__init__.py:808: RuntimeWarning: DateTimeField received a naive datetime (2019-03-08 10:52:57.870984) while time zone support is active.
  RuntimeWarning)
[2019-03-08 10:53:02,095: WARNING/Worker-26] OptiModel full clean - default to full clean
[2019-03-08 10:53:02,096: WARNING/Worker-26] Traceback (most recent call last):
[2019-03-08 10:53:02,096: WARNING/Worker-26] File "/home/device42/device42-new/device42/d42django/OptiModel.py", line 75, in opt_full_clean
[2019-03-08 10:53:02,096: WARNING/Worker-26] File "/usr/lib/python2.7/site-packages/django/db/models/base.py", line 824, in full_clean
[2019-03-08 10:53:02,096: WARNING/Worker-26] raise ValidationError(errors)
[2019-03-08 10:53:02,096: WARNING/Worker-26] ValidationError: {'__all__': [u'Object with same name already exists.']}
[2019-03-08 10:53:02,096: WARNING/Worker-26] failure in process_device_bulk_data for
[2019-03-08 10:53:02,096: WARNING/Worker-26] {u'macaddress': u'1C:40:24:3B:71:10', u'port_name': u'QLogic BCM57810 10 Gigabit Ethernet (NDIS VBD Client)_d42', 'device_id': 9942}
[2019-03-08 10:53:02,096: WARNING/Worker-26] {'__all__': [u'Object with same name already exists.']}
[2019-03-08 10:53:02,097: WARNING/Worker-26] failure in process_device_bulk_data
[2019-03-08 10:53:02,097: WARNING/Worker-26] Traceback (most recent call last):
[2019-03-08 10:53:02,097: WARNING/Worker-26] File "/home/device42/device42-new/device42/rackraj/CustomFunctions.py", line 12552, in process_device_bulk_data
[2019-03-08 10:53:02,097: WARNING/Worker-26] File "/home/device42/device42-new/device42/rackraj/CustomFunctions.py", line 5136, in mactable_post_api
[2019-03-08 10:53:02,097: WARNING/Worker-26] File "/home/device42/device42-new/device42/d42django/OptiModel.py", line 87, in full_clean
[2019-03-08 10:53:02,097: WARNING/Worker-26] File "/home/device42/device42-new/device42/d42django/OptiModel.py", line 75, in opt_full_clean
[2019-03-08 10:53:02,097: WARNING/Worker-26] File "/usr/lib/python2.7/site-packages/django/db/models/base.py", line 824, in full_clean
[2019-03-08 10:53:02,097: WARNING/Worker-26] raise ValidationError(errors)
[2019-03-08 10:53:02,097: WARNING/Worker-26] ValidationError: {'__all__': [u'Object with same name already exists.']}
[2019-03-08 10:53:02,109: WARNING/Worker-26] failure in process_device_bulk_data for
[2019-03-08 10:53:02,109: WARNING/Worker-26] {u'macaddress': u'02:FF:46:2E:AE:77', u'port_name': u'Microsoft Failover Cluster Virtual Adapter', 'device_id': 512}
[2019-03-08 10:53:02,109: WARNING/Worker-26] Another port with different mac exists.
[2019-03-08 10:53:02,109: WARNING/Worker-26] failure in process_device_bulk_data
[2019-03-08 10:53:02,109: WARNING/Worker-26] Traceback (most recent call last):
[2019-03-08 10:53:02,109: WARNING/Worker-26] File "/home/device42/device42-new/device42/rackraj/CustomFunctions.py", line 12552, in process_device_bulk_data
[2019-03-08 10:53:02,110: WARNING/Worker-26] File "/home/device42/device42-new/device42/rackraj/CustomFunctions.py", line 5091, in mactable_post_api
[2019-03-08 10:53:02,110: WARNING/Worker-26] AppError: Another port with different mac exists.
[2019-03-08 10:53:02,117: INFO/MainProcess] Received task: rackraj.tasks.QueuedJobRun[40a330a2-a673-4593-93ba-0742fa819768]
[2019-03-08 10:53:02,228: WARNING/Worker-26] /usr/lib/python2.7/site-packages/django/db/models/fields/__init__.py:808: RuntimeWarning: DateTimeField received a naive datetime (2019-03-08 10:53:02.226428) while time zone support is active.
  RuntimeWarning)
[2019-03-08 10:53:06,145: WARNING/Worker-3] /usr/lib/python2.7/site-packages/django/db/models/fields/__init__.py:808: RuntimeWarning: DateTimeField received a naive datetime (2019-03-08 10:52:59.735788) while time zone support is active.
  RuntimeWarning)
[2019-03-08 10:53:06,562: WARNING/Worker-3] failure in process_device_bulk_data for
[2019-03-08 10:53:06,562: WARNING/Worker-3] {u'macaddress': u'02:CE:8B:2D:9A:7A', u'port_name': u'device_id'}
[2019-03-08 10:53:06,563: WARNING/Worker-3] Another port with different mac exists.
[2019-03-08 10:53:06,563: WARNING/Worker-3] failure in process_device_bulk_data
[2019-03-08 10:53:06,563: WARNING/Worker-3] Traceback (most recent call last):
[2019-03-08 10:53:06,563: WARNING/Worker-3] File "/home/device42/device42-new/device42/rackraj/CustomFunctions.py", line 12552, in process_device_bulk_data
[2019-03-08 10:53:06,563: WARNING/Worker-3] File "/home/device42/device42-new/device42/rackraj/CustomFunctions.py", line 5091, in mactable_post_api
[2019-03-08 10:53:06,563: WARNING/Worker-3] AppError: Another port with different mac exists.
[2019-03-08 10:53:06,564: WARNING/Worker-5] /usr/lib/python2.7/site-packages/django/db/models/fields/__init__.py:808: RuntimeWarning: DateTimeField received a naive datetime (2019-03-08 10:53:02.278033) while time zone support is active.
  RuntimeWarning)
[2019-03-08 10:53:06,688: WARNING/Worker-3] /usr/lib/python2.7/site-packages/django/db/models/fields/__init__.py:808: RuntimeWarning: DateTimeField received a naive datetime (2019-03-08 10:53:06.686773) while time zone support is active.
  RuntimeWarning)
[2019-03-08 10:53:06,841: WARNING/Worker-5] failure in process_device_bulk_data for
[2019-03-08 10:53:06,841: WARNING/Worker-5] {u'macaddress': u'02:B8:B3:03:98:84', u'port_name': u'Microsoft Failover Cluster Virtual Adapter', 'device_id': 4834}
[2019-03-08 10:53:06,841: WARNING/Worker-5] Another port with different mac exists.
[2019-03-08 10:53:06,841: WARNING/Worker-5] failure in process_device_bulk_data
[2019-03-08 10:53:06,841: WARNING/Worker-5] Traceback (most recent call last):
[2019-03-08 10:53:06,841: WARNING/Worker-5] File "/home/device42/device42-new/device42/rackraj/CustomFunctions.py", line 12552, in process_device_bulk_data
[2019-03-08 10:53:06,841: WARNING/Worker-5] File "/home/device42/device42-new/device42/rackraj/CustomFunctions.py", line 5091, in mactable_post_api
[2019-03-08 10:53:06,841: WARNING/Worker-5] AppError: Another port with different mac exists.
[2019-03-08 10:53:06,866: WARNING/Worker-3] /usr/lib/python2.7/site-packages/django/db/models/fields/__init__.py:808: RuntimeWarning: DateTimeField received a naive datetime (2019-03-08 10:53:06.864650) while time zone support is active.
  RuntimeWarning)
[2019-03-08 10:53:06,892: WARNING/Worker-5] OptiModel full clean - default to full clean
[2019-03-08 10:53:06,892: WARNING/Worker-5] Traceback (most recent call last):
[2019-03-08 10:53:06,892: WARNING/Worker-5] File "/home/device42/device42-new/device42/d42django/OptiModel.py", line 75, in opt_full_clean
[2019-03-08 10:53:06,892: WARNING/Worker-5] File "/usr/lib/python2.7/site-packages/django/db/models/base.py", line 824, in full_clean
[2019-03-08 10:53:06,892: WARNING/Worker-5] raise ValidationError(errors)
[2019-03-08 10:53:06,892: WARNING/Worker-5] ValidationError: {'__all__': [u'Object with same name already exists.']}
[2019-03-08 10:53:06,893: WARNING/Worker-5] failure in process_device_bulk_data for
[2019-03-08 10:53:06,893: WARNING/Worker-5] {u'macaddress': u'1C:40:24:36:5E:90', u'port_name': u'QLogic BCM57810 10 Gigabit Ethernet (NDIS VBD Client)_d42', 'device_id': 9757}
[2019-03-08 10:53:06,893: WARNING/Worker-5] {'__all__': [u'Object with same name already exists.']}
[2019-03-08 10:53:06,893: WARNING/Worker-5] failure in process_device_bulk_data
[2019-03-08 10:53:06,893: WARNING/Worker-5] Traceback (most recent call last):
[2019-03-08 10:53:06,893: WARNING/Worker-5] File "/home/device42/device42-new/device42/rackraj/CustomFunctions.py", line 12552, in process_device_bulk_data
[2019-03-08 10:53:06,893: WARNING/Worker-5] File "/home/device42/device42-new/device42/rackraj/CustomFunctions.py", line 5136, in mactable_post_api
[2019-03-08 10:53:06,894: WARNING/Worker-5] File "/home/device42/device42-new/device42/d42django/OptiModel.py", line 87, in full_clean
[2019-03-08 10:53:06,894: WARNING/Worker-5] File "/home/device42/device42-new/device42/d42django/OptiModel.py", line 75, in opt_full_clean
[2019-03-08 10:53:06,894: WARNING/Worker-5] File "/usr/lib/python2.7/site-packages/django/db/models/base.py", line 824, in full_clean
[2019-03-08 10:53:06,894: WARNING/Worker-5] raise ValidationError(errors)
[2019-03-08 10:53:06,894: WARNING/Worker-5] ValidationError: {'__all__': [u'Object with same name already exists.']}
[2019-03-08 10:53:07,063: WARNING/Worker-5] /usr/lib/python2.7/site-packages/django/db/models/fields/__init__.py:808: RuntimeWarning: DateTimeField received a naive datetime (2019-03-08 10:53:07.061807) while time zone support is active.
  RuntimeWarning)
[2019-03-08 10:53:07,239: WARNING/Worker-5] /usr/lib/python2.7/site-packages/django/db/models/fields/__init__.py:808: RuntimeWarning: DateTimeField received a naive datetime (2019-03-08 10:53:07.237280) while time zone support is active.
  RuntimeWarning)
[2019-03-08 10:53:07,672: WARNING/Worker-26] /usr/lib/python2.7/site-packages/django/db/models/fields/__init__.py:808: RuntimeWarning: DateTimeField received a naive datetime (2019-03-08 10:53:01.979592) while time zone support is active.
  RuntimeWarning)
[2019-03-08 10:53:07,949: WARNING/Worker-26] failure in process_device_bulk_data for
[2019-03-08 10:53:07,950: WARNING/Worker-26] {u'macaddress': u'02:54:BF:47:8A:F8', u'port_name': u'Microsoft Failover Cluster Virtual Adapter', 'device_id': 598}
[2019-03-08 10:53:07,950: WARNING/Worker-26] Another port with different mac exists.
[2019-03-08 10:53:07,950: WARNING/Worker-26] failure in process_device_bulk_data
[2019-03-08 10:53:07,950: WARNING/Worker-26] Traceback (most recent call last):
[2019-03-08 10:53:07,950: WARNING/Worker-26] File "/home/device42/device42-new/device42/rackraj/CustomFunctions.py", line 12552, in process_device_bulk_data
[2019-03-08 10:53:07,950: WARNING/Worker-26] File "/home/device42/device42-new/device42/rackraj/CustomFunctions.py", line 5091, in mactable_post_api
[2019-03-08 10:53:07,950: WARNING/Worker-26] AppError: Another port with different mac exists.
[2019-03-08 10:53:08,096: WARNING/Worker-26] /usr/lib/python2.7/site-packages/django/db/models/fields/__init__.py:808: RuntimeWarning: DateTimeField received a naive datetime (2019-03-08 10:53:08.094648) while time zone support is active.
  RuntimeWarning)
[2019-03-08 10:53:11,890: WARNING/Worker-5] /usr/lib/python2.7/site-packages/django/db/models/fields/__init__.py:808: RuntimeWarning: DateTimeField received a naive datetime (2019-03-08 10:53:06.749824) while time zone support is active.
  RuntimeWarning)
[2019-03-08 10:53:12,131: WARNING/Worker-5] failure in process_device_bulk_data for
[2019-03-08 10:53:12,131: WARNING/Worker-5] {u'macaddress': u'02:15:3C:43:58:BD', u'port_name': u'Microsoft Failover Cluster Virtual Adapter', 'device_id': 31831}
[2019-03-08 10:53:12,132: WARNING/Worker-5] Another port with different mac exists.
[2019-03-08 10:53:12,132: WARNING/Worker-5] failure in process_device_bulk_data
[2019-03-08 10:53:12,132: WARNING/Worker-5] Traceback (most recent call last):
[2019-03-08 10:53:12,132: WARNING/Worker-5] File "/home/device42/device42-new/device42/rackraj/CustomFunctions.py", line 12552, in process_device_bulk_data
[2019-03-08 10:53:12,132: WARNING/Worker-5] File "/home/device42/device42-new/device42/rackraj/CustomFunctions.py", line 5091, in mactable_post_api
[2019-03-08 10:53:12,132: WARNING/Worker-5] AppError: Another port with different mac exists.
[2019-03-08 10:53:12,280: WARNING/Worker-5] /usr/lib/python2.7/site-packages/django/db/models/fields/__init__.py:808: RuntimeWarning: DateTimeField received a naive datetime (2019-03-08 10:53:12.278587) while time zone support is active.
  RuntimeWarning)
[2019-03-08 10:53:12,417: WARNING/Worker-3] /usr/lib/python2.7/site-packages/django/db/models/fields/__init__.py:808: RuntimeWarning: DateTimeField received a naive datetime (2019-03-08 10:53:06.386678) while time zone support is active.
  RuntimeWarning)
[2019-03-08 10:53:13,331: WARNING/Worker-26] /usr/lib/python2.7/site-packages/django/db/models/fields/__init__.py:808: RuntimeWarning: DateTimeField received a naive datetime (2019-03-08 10:53:07.798622) while time zone support is active.
  RuntimeWarning)
[2019-03-08 10:53:13,527: WARNING/Worker-26] failure in process_device_bulk_data for
[2019-03-08 10:53:13,527: WARNING/Worker-26] {u'macaddress': u'02:8A:C6:09:30:C5', u'port_name': u'Microsoft Failover Cluster Virtual Adapter', 'device_id': 31828}
[2019-03-08 10:53:13,527: WARNING/Worker-26] Another port with different mac exists.
[2019-03-08 10:53:13,527: WARNING/Worker-26] failure in process_device_bulk_data
[2019-03-08 10:53:13,527: WARNING/Worker-26] Traceback (most recent call last):
[2019-03-08 10:53:13,527: WARNING/Worker-26] File "/home/device42/device42-new/device42/rackraj/CustomFunctions.py", line 12552, in process_device_bulk_data
[2019-03-08 10:53:13,527: WARNING/Worker-26] File "/home/device42/device42-new/device42/rackraj/CustomFunctions.py", line 5091, in mactable_post_api
[2019-03-08 10:53:13,527: WARNING/Worker-26] AppError: Another port with different mac exists.
[2019-03-08 10:53:13,678: WARNING/Worker-26] /usr/lib/python2.7/site-packages/django/db/models/fields/__init__.py:808: RuntimeWarning: DateTimeField received a naive datetime (2019-03-08 10:53:13.676264) while time zone support is active.
  RuntimeWarning)
[2019-03-08 10:53:18,132: WARNING/Worker-5] /usr/lib/python2.7/site-packages/django/db/models/fields/__init__.py:808: RuntimeWarning: DateTimeField received a naive datetime (2019-03-08 10:53:12.044466) while time zone support is active.
  RuntimeWarning)
[2019-03-08 10:53:20,038: WARNING/Worker-26] /usr/lib/python2.7/site-packages/django/db/models/fields/__init__.py:808: RuntimeWarning: DateTimeField received a naive datetime (2019-03-08 10:53:13.433808) while time zone support is active.
  RuntimeWarning)
[2019-03-08 10:53:22,092: WARNING/Worker-3] /usr/lib/python2.7/site-packages/django/db/models/fields/__init__.py:808: RuntimeWarning: DateTimeField received a naive datetime (2019-03-08 10:53:12.569128) while time zone support is active.
  RuntimeWarning)
[2019-03-08 10:53:23,744: WARNING/Worker-26] /usr/lib/python2.7/site-packages/django/db/models/fields/__init__.py:808: RuntimeWarning: DateTimeField received a naive datetime (2019-03-08 10:53:20.166849) while time zone support is active.
  RuntimeWarning)
[2019-03-08 10:53:24,042: WARNING/Worker-26] failure in process_device_bulk_data for
[2019-03-08 10:53:24,042: WARNING/Worker-26] {u'macaddress': u'1C:40:24:36:5E:B7', u'port_name': u'QLogic BCM57810 10 Gigabit Ethernet (NDIS VBD Client)_d42', 'device_id': 4622}
[2019-03-08 10:53:24,042: WARNING/Worker-26] Another port with different mac exists.
[2019-03-08 10:53:24,042: WARNING/Worker-26] failure in process_device_bulk_data
[2019-03-08 10:53:24,042: WARNING/Worker-26] Traceback (most recent call last):
[2019-03-08 10:53:24,042: WARNING/Worker-26] File "/home/device42/device42-new/device42/rackraj/CustomFunctions.py", line 12552, in process_device_bulk_data
[2019-03-08 10:53:24,042: WARNING/Worker-26] File "/home/device42/device42-new/device42/rackraj/CustomFunctions.py", line 5091, in mactable_post_api
[2019-03-08 10:53:24,042: WARNING/Worker-26] AppError: Another port with different mac exists.
HINT:  See server log for query details.
[2019-03-08 10:54:15,632: WARNING/Worker-11] app database failed in process_device_bulk_data
[2019-03-08 10:54:15,632: WARNING/Worker-11] Traceback (most recent call last):
[2019-03-08 10:54:15,632: WARNING/Worker-11] File "/home/device42/device42-new/device42/rackraj/CustomFunctions.py", line 12677, in process_device_bulk_data
[2019-03-08 10:54:15,633: WARNING/Worker-11] File "/home/device42/device42-new/device42/rackraj/applications.py", line 102, in database_add_or_edit_api
[2019-03-08 10:54:15,633: WARNING/Worker-11] File "/home/device42/device42-new/device42/rackraj/CustomFunctions.py", line 10340, in service_detail_add_edit_api
[2019-03-08 10:54:15,633: WARNING/Worker-11] File "/home/device42/device42-new/device42/rackraj/CustomFunctions.py", line 10283, in service_add_edit_api
[2019-03-08 10:54:15,633: WARNING/Worker-11] File "/home/device42/device42-new/device42/d42django/OptiModel.py", line 84, in save
[2019-03-08 10:54:15,633: WARNING/Worker-11] File "/home/device42/device42-new/device42/d42django/OptiModel.py", line 49, in opt_save
[2019-03-08 10:54:15,633: WARNING/Worker-11] File "/usr/lib/python2.7/site-packages/django/db/models/base.py", line 463, in save
[2019-03-08 10:54:15,633: WARNING/Worker-11] self.save_base(using=using, force_insert=force_insert, force_update=force_update)
[2019-03-08 10:54:15,633: WARNING/Worker-11] File "/usr/lib/python2.7/site-packages/django/db/models/base.py", line 529, in save_base
[2019-03-08 10:54:15,633: WARNING/Worker-11] rows = manager.using(using).filter(pk=pk_val)._update(values)
[2019-03-08 10:54:15,633: WARNING/Worker-11] File "/usr/lib/python2.7/site-packages/django/db/models/query.py", line 560, in _update
[2019-03-08 10:54:15,633: WARNING/Worker-11] return query.get_compiler(self.db).execute_sql(None)
[2019-03-08 10:54:15,633: WARNING/Worker-11] File "/usr/lib/python2.7/site-packages/django/db/models/sql/compiler.py", line 988, in execute_sql
[2019-03-08 10:54:15,633: WARNING/Worker-11] cursor = super(SQLUpdateCompiler, self).execute_sql(result_type)
[2019-03-08 10:54:15,634: WARNING/Worker-11] File "/usr/lib/python2.7/site-packages/django/db/models/sql/compiler.py", line 818, in execute_sql
[2019-03-08 10:54:15,634: WARNING/Worker-11] cursor.execute(sql, params)
[2019-03-08 10:54:15,634: WARNING/Worker-11] File "/usr/lib/python2.7/site-packages/django/db/backends/postgresql_psycopg2/base.py", line 52, in execute
[2019-03-08 10:54:15,634: WARNING/Worker-11] return self.cursor.execute(query, args)
[2019-03-08 10:54:15,634: WARNING/Worker-11] DatabaseError: deadlock detected
DETAIL:  Process 17442 waits for ExclusiveLock on tuple (85688,41) of relation 16999 of database 16384; blocked by process 15595.
Process 15595 waits for ShareLock on transaction 534113732; blocked by process 16778.
Process 16778 waits for ShareLock on transaction 534112561; blocked by process 17442.
HINT:  See server log for query details.
[2019-03-08 10:54:17,869: WARNING/Worker-5] /usr/lib/python2.7/site-packages/django/db/models/fields/__init__.py:808: RuntimeWarning: DateTimeField received a naive datetime (2019-03-08 10:54:09.111492) while time zone support is active.
  RuntimeWarning)
[2019-03-08 10:54:18,204: WARNING/Worker-5] /usr/lib/python2.7/site-packages/django/db/models/fields/__init__.py:808: RuntimeWarning: DateTimeField received a naive datetime (2019-03-08 10:54:18.202889) while time zone support is active.
  RuntimeWarning)
[2019-03-08 10:54:20,934: WARNING/Worker-11] /usr/lib/python2.7/site-packages/django/db/models/fields/__init__.py:808: RuntimeWarning: DateTimeField received a naive datetime (2019-03-08 10:54:02.272868) while time zone support is active.
  RuntimeWarning)
[2019-03-08 10:54:21,445: WARNING/Worker-26] /usr/lib/python2.7/site-packages/django/db/models/fields/__init__.py:808: RuntimeWarning: DateTimeField received a naive datetime (2019-03-08 10:54:08.727895) while time zone support is active.
  RuntimeWarning)
[2019-03-08 10:54:21,618: INFO/MainProcess] Task rackraj.tasks.QueuedJobRun[ff7dd4bf-2e76-4960-8e15-da4b08ce36c1] succeeded in 139.514950324s: None
[2019-03-08 10:54:21,732: WARNING/Worker-11] failure in process_device_bulk_data for
[2019-03-08 10:54:21,733: WARNING/Worker-11] {u'macaddress': u'02:E6:A2:0D:AB:76', u'port_name': u'Microsoft Failover Cluster Virtual Adapter', 'device_id': 31858}
[2019-03-08 10:54:21,733: WARNING/Worker-11] Another port with different mac exists.
[2019-03-08 10:54:21,733: WARNING/Worker-11] failure in process_device_bulk_data
[2019-03-08 10:54:21,733: WARNING/Worker-11] Traceback (most recent call last):
[2019-03-08 10:54:21,733: WARNING/Worker-11] File "/home/device42/device42-new/device42/rackraj/CustomFunctions.py", line 12552, in process_device_bulk_data
[2019-03-08 10:54:21,733: WARNING/Worker-11] File "/home/device42/device42-new/device42/rackraj/CustomFunctions.py", line 5091, in mactable_post_api
[2019-03-08 10:54:21,733: WARNING/Worker-11] AppError: Another port with different mac exists.
[2019-03-08 10:54:21,896: WARNING/Worker-11] /usr/lib/python2.7/site-packages/django/db/models/fields/__init__.py:808: RuntimeWarning: DateTimeField received a naive datetime (2019-03-08 10:54:21.894520) while time zone support is active.
  RuntimeWarning)
[2019-03-08 10:59:52,163: WARNING/Worker-16] OptiModel full clean - default to full clean
[2019-03-08 10:59:52,163: WARNING/Worker-16] Traceback (most recent call last):
[2019-03-08 10:59:52,163: WARNING/Worker-16] File "/home/device42/device42-new/device42/d42django/OptiModel.py", line 49, in opt_save
[2019-03-08 10:59:52,163: WARNING/Worker-16] File "/usr/lib/python2.7/site-packages/django/db/models/base.py", line 463, in save
[2019-03-08 10:59:52,164: WARNING/Worker-16] self.save_base(using=using, force_insert=force_insert, force_update=force_update)
[2019-03-08 10:59:52,164: WARNING/Worker-16] File "/usr/lib/python2.7/site-packages/django/db/models/base.py", line 529, in save_base
[2019-03-08 10:59:52,164: WARNING/Worker-16] rows = manager.using(using).filter(pk=pk_val)._update(values)
[2019-03-08 10:59:52,164: WARNING/Worker-16] File "/usr/lib/python2.7/site-packages/django/db/models/query.py", line 560, in _update
[2019-03-08 10:59:52,164: WARNING/Worker-16] return query.get_compiler(self.db).execute_sql(None)
[2019-03-08 10:59:52,164: WARNING/Worker-16] File "/usr/lib/python2.7/site-packages/django/db/models/sql/compiler.py", line 988, in execute_sql
[2019-03-08 10:59:52,165: WARNING/Worker-16] cursor = super(SQLUpdateCompiler, self).execute_sql(result_type)
[2019-03-08 10:59:52,165: WARNING/Worker-16] File "/usr/lib/python2.7/site-packages/django/db/models/sql/compiler.py", line 818, in execute_sql
[2019-03-08 10:59:52,165: WARNING/Worker-16] cursor.execute(sql, params)
[2019-03-08 10:59:52,165: WARNING/Worker-16] File "/usr/lib/python2.7/site-packages/django/db/backends/postgresql_psycopg2/base.py", line 52, in execute
[2019-03-08 10:59:52,165: WARNING/Worker-16] return self.cursor.execute(query, args)
[2019-03-08 10:59:52,165: WARNING/Worker-16] IntegrityError: duplicate key value violates unique constraint "rackraj_theservice_displayname_name_key"
DETAIL:  Key (md5(upper(displayname)), md5(upper(name)))=(f5e04d340f7ea73940f3a8b4fe173661, 21f1fe4b0a60c81fc437760d9f24d429) already exists.
[2019-03-08 10:59:52,166: WARNING/Worker-16] service port failed in process_device_bulk_data for
[2019-03-08 10:59:52,166: WARNING/Worker-16] {u'discovered_service': u'PServer.exe', u'remote_port_time': u'2019-03-08 02:45:03', u'listening_ip': u'11.11.211.82', u'discovered_service_display_name': u'D:\\PServer.exe ', u'remote_ips': u'11.11.225.74:(45198)_d42', u'port': 2100, 'device_id': 656}
[2019-03-08 10:59:52,166: WARNING/Worker-16] duplicate key value violates unique constraint "rackraj_theservice_displayname_name_key"
DETAIL:  Key (md5(upper(displayname)), md5(upper(name)))=(f5e04d340f7ea73940f3a8b4fe173661, 21f1fe4b0a60c81fc437760d9f24d429) already exists.
[2019-03-08 10:59:52,166: WARNING/Worker-16] service port failed in process_device_bulk_data
[2019-03-08 10:59:52,166: WARNING/Worker-16] Traceback (most recent call last):
[2019-03-08 10:59:52,166: WARNING/Worker-16] File "/home/device42/device42-new/device42/rackraj/CustomFunctions.py", line 12714, in process_device_bulk_data
[2019-03-08 10:59:52,166: WARNING/Worker-16] File "/home/device42/device42-new/device42/rackraj/CustomFunctions.py", line 11156, in service_ports_add_edit_api_settup
[2019-03-08 10:59:52,166: WARNING/Worker-16] File "/home/device42/device42-new/device42/rackraj/CustomFunctions.py", line 10340, in service_detail_add_edit_api
[2019-03-08 10:59:52,166: WARNING/Worker-16] File "/home/device42/device42-new/device42/rackraj/CustomFunctions.py", line 10283, in service_add_edit_api
[2019-03-08 10:59:52,166: WARNING/Worker-16] File "/home/device42/device42-new/device42/d42django/OptiModel.py", line 84, in save
[2019-03-08 10:59:52,166: WARNING/Worker-16] File "/home/device42/device42-new/device42/d42django/OptiModel.py", line 49, in opt_save
[2019-03-08 10:59:52,166: WARNING/Worker-16] File "/usr/lib/python2.7/site-packages/django/db/models/base.py", line 463, in save
[2019-03-08 10:59:52,167: WARNING/Worker-16] self.save_base(using=using, force_insert=force_insert, force_update=force_update)
[2019-03-08 10:59:52,167: WARNING/Worker-16] File "/usr/lib/python2.7/site-packages/django/db/models/base.py", line 529, in save_base
[2019-03-08 10:59:52,167: WARNING/Worker-16] rows = manager.using(using).filter(pk=pk_val)._update(values)
[2019-03-08 10:59:52,167: WARNING/Worker-16] File "/usr/lib/python2.7/site-packages/django/db/models/query.py", line 560, in _update
[2019-03-08 10:59:52,167: WARNING/Worker-16] return query.get_compiler(self.db).execute_sql(None)
[2019-03-08 10:59:52,167: WARNING/Worker-16] File "/usr/lib/python2.7/site-packages/django/db/models/sql/compiler.py", line 988, in execute_sql
[2019-03-08 10:59:52,167: WARNING/Worker-16] cursor = super(SQLUpdateCompiler, self).execute_sql(result_type)
[2019-03-08 10:59:52,167: WARNING/Worker-16] File "/usr/lib/python2.7/site-packages/django/db/models/sql/compiler.py", line 818, in execute_sql
[2019-03-08 10:59:52,167: WARNING/Worker-16] cursor.execute(sql, params)
[2019-03-08 10:59:52,167: WARNING/Worker-16] File "/usr/lib/python2.7/site-packages/django/db/backends/postgresql_psycopg2/base.py", line 52, in execute
[2019-03-08 10:59:52,167: WARNING/Worker-16] return self.cursor.execute(query, args)
[2019-03-08 10:59:52,167: WARNING/Worker-16] IntegrityError: duplicate key value violates unique constraint "rackraj_theservice_displayname_name_key"
DETAIL:  Key (md5(upper(displayname)), md5(upper(name)))=(f5e04d340f7ea73940f3a8b4fe173661, 21f1fe4b0a60c81fc437760d9f24d429) already exists.
[2019-03-08 10:59:52,173: WARNING/Worker-16] OptiModel full clean - default to full clean
[2019-03-08 10:59:52,173: WARNING/Worker-16] Traceback (most recent call last):
[2019-03-08 10:59:52,173: WARNING/Worker-16] File "/home/device42/device42-new/device42/d42django/OptiModel.py", line 49, in opt_save
[2019-03-08 10:59:52,173: WARNING/Worker-16] File "/usr/lib/python2.7/site-packages/django/db/models/base.py", line 463, in save
[2019-03-08 10:59:52,173: WARNING/Worker-16] self.save_base(using=using, force_insert=force_insert, force_update=force_update)
[2019-03-08 10:59:52,174: WARNING/Worker-16] File "/usr/lib/python2.7/site-packages/django/db/models/base.py", line 529, in save_base
[2019-03-08 10:59:52,174: WARNING/Worker-16] rows = manager.using(using).filter(pk=pk_val)._update(values)
[2019-03-08 10:59:52,174: WARNING/Worker-16] File "/usr/lib/python2.7/site-packages/django/db/models/query.py", line 560, in _update
[2019-03-08 10:59:52,174: WARNING/Worker-16] return query.get_compiler(self.db).execute_sql(None)
[2019-03-08 10:59:52,174: WARNING/Worker-16] File "/usr/lib/python2.7/site-packages/django/db/models/sql/compiler.py", line 988, in execute_sql
[2019-03-08 10:59:52,174: WARNING/Worker-16] cursor = super(SQLUpdateCompiler, self).execute_sql(result_type)
[2019-03-08 10:59:52,174: WARNING/Worker-16] File "/usr/lib/python2.7/site-packages/django/db/models/sql/compiler.py", line 818, in execute_sql
[2019-03-08 10:59:52,174: WARNING/Worker-16] cursor.execute(sql, params)
[2019-03-08 10:59:52,174: WARNING/Worker-16] File "/usr/lib/python2.7/site-packages/django/db/backends/postgresql_psycopg2/base.py", line 52, in execute
[2019-03-08 10:59:52,174: WARNING/Worker-16] return self.cursor.execute(query, args)
[2019-03-08 10:59:52,174: WARNING/Worker-16] IntegrityError: duplicate key value violates unique constraint "rackraj_theservice_displayname_name_key"
DETAIL:  Key (md5(upper(displayname)), md5(upper(name)))=(f5e04d340f7ea73940f3a8b4fe173661, f179f63f45f4f5dfd168300736546f2a) already exists.
[2019-03-08 10:59:52,175: WARNING/Worker-16] service port failed in process_device_bulk_data for
[2019-03-08 10:59:52,175: WARNING/Worker-16] {u'discovered_service': u'PServer.exe', u'remote_port_time': u'2019-03-08 02:45:03', u'listening_ip': u'11.11.211.82', u'discovered_service_display_name': u'D:\\PServer.exe ', u'remote_ips': u'11.11.225.74:(47994)', u'port': 2101, 'device_id': 598}
[2019-03-08 10:59:52,175: WARNING/Worker-16] duplicate key value violates unique constraint "rackraj_theservice_displayname_name_key"
DETAIL:  Key (md5(upper(displayname)), md5(upper(name)))=(f5e04d340f7ea73940f3a8b4fe173661, f179f63f45f4f5dfd168300736546f2a) already exists.
[2019-03-08 10:59:52,175: WARNING/Worker-16] service port failed in process_device_bulk_data
[2019-03-08 10:59:52,175: WARNING/Worker-16] Traceback (most recent call last):
[2019-03-08 10:59:52,175: WARNING/Worker-16] File "/home/device42/device42-new/device42/rackraj/CustomFunctions.py", line 12714, in process_device_bulk_data
[2019-03-08 10:59:52,175: WARNING/Worker-16] File "/home/device42/device42-new/device42/rackraj/CustomFunctions.py", line 11156, in service_ports_add_edit_api_settup
[2019-03-08 10:59:52,175: WARNING/Worker-16] File "/home/device42/device42-new/device42/rackraj/CustomFunctions.py", line 10340, in service_detail_add_edit_api
[2019-03-08 10:59:52,175: WARNING/Worker-16] File "/home/device42/device42-new/device42/rackraj/CustomFunctions.py", line 10283, in service_add_edit_api
[2019-03-08 10:59:52,175: WARNING/Worker-16] File "/home/device42/device42-new/device42/d42django/OptiModel.py", line 84, in save
[2019-03-08 10:59:52,175: WARNING/Worker-16] File "/home/device42/device42-new/device42/d42django/OptiModel.py", line 49, in opt_save
[2019-03-08 10:59:52,175: WARNING/Worker-16] File "/usr/lib/python2.7/site-packages/django/db/models/base.py", line 463, in save
[2019-03-08 10:59:52,176: WARNING/Worker-16] self.save_base(using=using, force_insert=force_insert, force_update=force_update)
[2019-03-08 10:59:52,176: WARNING/Worker-16] File "/usr/lib/python2.7/site-packages/django/db/models/base.py", line 529, in save_base
[2019-03-08 10:59:52,176: WARNING/Worker-16] rows = manager.using(using).filter(pk=pk_val)._update(values)
[2019-03-08 10:59:52,176: WARNING/Worker-16] File "/usr/lib/python2.7/site-packages/django/db/models/query.py", line 560, in _update
[2019-03-08 10:59:52,176: WARNING/Worker-16] return query.get_compiler(self.db).execute_sql(None)
[2019-03-08 10:59:52,176: WARNING/Worker-16] File "/usr/lib/python2.7/site-packages/django/db/models/sql/compiler.py", line 988, in execute_sql
[2019-03-08 10:59:52,176: WARNING/Worker-16] cursor = super(SQLUpdateCompiler, self).execute_sql(result_type)
[2019-03-08 10:59:52,176: WARNING/Worker-16] File "/usr/lib/python2.7/site-packages/django/db/models/sql/compiler.py", line 818, in execute_sql
[2019-03-08 10:59:52,176: WARNING/Worker-16] cursor.execute(sql, params)
[2019-03-08 10:59:52,176: WARNING/Worker-16] File "/usr/lib/python2.7/site-packages/django/db/backends/postgresql_psycopg2/base.py", line 52, in execute
[2019-03-08 10:59:52,176: WARNING/Worker-16] return self.cursor.execute(query, args)
[2019-03-08 16:22:02,075: INFO/MainProcess] Received task: rackraj.tasks.QueuedJobRun[60183149-96a4-4eca-8130-15351dd253ea]
[2019-03-08 16:22:02,097: INFO/MainProcess] Task rackraj.tasks.QueuedJobRun[60183149-96a4-4eca-8130-15351dd253ea] succeeded in 0.0194173240016s: None
[2019-03-08 16:23:02,119: INFO/MainProcess] Received task: rackraj.tasks.QueuedJobRun[3dfad5c5-900c-4edb-8d1d-8201587c5fae]
[2019-03-08 16:23:02,140: INFO/MainProcess] Task rackraj.tasks.QueuedJobRun[3dfad5c5-900c-4edb-8d1d-8201587c5fae] succeeded in 0.0175145169997s: None
[2019-03-08 16:24:02,069: INFO/MainProcess] Received task: rackraj.tasks.QueuedJobRun[64b79959-03e2-413b-be28-a3dc2c53994f]
[2019-03-08 16:24:02,093: INFO/MainProcess] Task rackraj.tasks.QueuedJobRun[64b79959-03e2-413b-be28-a3dc2c53994f] succeeded in 0.0197503950003s: None
[2019-03-08 16:25:02,064: INFO/MainProcess] Received task: rackraj.tasks.QueuedJobRun[6ea9c820-6fdc-4b87-849a-edca5f7ae1fa]
[2019-03-08 16:25:02,087: INFO/MainProcess] Task rackraj.tasks.QueuedJobRun[6ea9c820-6fdc-4b87-849a-edca5f7ae1fa] succeeded in 0.019740355001s: None
[2019-03-08 16:26:02,111: INFO/MainProcess] Received task: rackraj.tasks.QueuedJobRun[7a1e6b85-19d0-4630-9f36-6a99e4839313]
[2019-03-08 16:26:02,132: INFO/MainProcess] Task rackraj.tasks.QueuedJobRun[7a1e6b85-19d0-4630-9f36-6a99e4839313] succeeded in 0.0180583810034s: None
[2019-03-08 16:27:02,112: INFO/MainProcess] Received task: rackraj.tasks.QueuedJobRun[727de055-f251-479d-b3d8-26461802ea86]
[2019-03-08 16:27:02,134: INFO/MainProcess] Task rackraj.tasks.QueuedJobRun[727de055-f251-479d-b3d8-26461802ea86] succeeded in 0.0189689100007s: None
[2019-03-08 16:28:02,061: INFO/MainProcess] Received task: rackraj.tasks.QueuedJobRun[e0e04ccd-c3f2-4b0a-ba9d-08a9b4607cbc]
[2019-03-08 16:28:02,081: INFO/MainProcess] Task rackraj.tasks.QueuedJobRun[e0e04ccd-c3f2-4b0a-ba9d-08a9b4607cbc] succeeded in 0.0184104800028s: None
[2019-03-08 16:29:02,123: INFO/MainProcess] Received task: rackraj.tasks.QueuedJobRun[244082c8-aee1-45a1-986d-f418cb44f998]
[2019-03-08 16:29:02,145: INFO/MainProcess] Task rackraj.tasks.QueuedJobRun[244082c8-aee1-45a1-986d-f418cb44f998] succeeded in 0.0190561730014s: None
[2019-03-08 16:30:02,062: INFO/MainProcess] Received task: rackraj.tasks.QueuedJobRun[5a0e6ea4-78ac-4d75-bec0-ca7af530cf8d]
[2019-03-08 16:30:02,087: INFO/MainProcess] Task rackraj.tasks.QueuedJobRun[5a0e6ea4-78ac-4d75-bec0-ca7af530cf8d] succeeded in 0.0225168500001s: None
[2019-03-08 16:31:02,093: INFO/MainProcess] Received task: rackraj.tasks.QueuedJobRun[c287e5a8-6bf0-42b6-981d-3c6a73cc5e46]
[2019-03-08 16:31:02,115: INFO/MainProcess] Task rackraj.tasks.QueuedJobRun[c287e5a8-6bf0-42b6-981d-3c6a73cc5e46] succeeded in 0.0189268350005s: None
[2019-03-08 16:32:02,071: INFO/MainProcess] Received task: rackraj.tasks.QueuedJobRun[06543e9a-3a85-4890-a0c2-00ea15cafafd]
[2019-03-08 16:32:02,097: INFO/MainProcess] Task rackraj.tasks.QueuedJobRun[06543e9a-3a85-4890-a0c2-00ea15cafafd] succeeded in 0.0226281299983s: None
[2019-03-08 16:33:02,064: INFO/MainProcess] Received task: rackraj.tasks.QueuedJobRun[40d9c310-db31-4870-9818-d5a0e18714d6]
[2019-03-08 16:33:02,087: INFO/MainProcess] Task rackraj.tasks.QueuedJobRun[40d9c310-db31-4870-9818-d5a0e18714d6] succeeded in 0.0201384230022s: None
[2019-03-08 16:34:02,113: INFO/MainProcess] Received task: rackraj.tasks.QueuedJobRun[8df08ac2-0405-4f41-af63-f357ef8ef51f]
[2019-03-08 16:35:02,134: INFO/MainProcess] Received task: rackraj.tasks.QueuedJobRun[062fe32a-a609-4ed4-afcd-26e80928f0e3]
[2019-03-08 16:35:02,157: INFO/MainProcess] Task rackraj.tasks.QueuedJobRun[062fe32a-a609-4ed4-afcd-26e80928f0e3] succeeded in 0.0196241329977s: None
[2019-03-08 16:36:02,119: INFO/MainProcess] Received task: rackraj.tasks.QueuedJobRun[8b8d6a5f-29ca-4889-8d3f-ec75bcc6c0eb]
[2019-03-08 16:36:02,139: INFO/MainProcess] Task rackraj.tasks.QueuedJobRun[8b8d6a5f-29ca-4889-8d3f-ec75bcc6c0eb] succeeded in 0.0176466770026s: None
[2019-03-08 16:36:45,935: INFO/MainProcess] Task rackraj.tasks.QueuedJobRun[8df08ac2-0405-4f41-af63-f357ef8ef51f] succeeded in 163.818848259s: None
[2019-03-08 16:37:02,072: INFO/MainProcess] Received task: rackraj.tasks.QueuedJobRun[03da2966-b0dd-4a90-a0fd-c486f95a8e33]
[2019-03-08 16:37:02,099: INFO/MainProcess] Task rackraj.tasks.QueuedJobRun[03da2966-b0dd-4a90-a0fd-c486f95a8e33] succeeded in 0.0245216420008s: None
[2019-03-08 16:38:02,113: INFO/MainProcess] Received task: rackraj.tasks.QueuedJobRun[cafa2867-20e5-4c42-a327-9a7a736f439a]
[2019-03-08 16:38:02,141: INFO/MainProcess] Task rackraj.tasks.QueuedJobRun[cafa2867-20e5-4c42-a327-9a7a736f439a] succeeded in 0.0210952509988s: None
[2019-03-08 16:39:02,122: INFO/MainProcess] Received task: rackraj.tasks.QueuedJobRun[1db6e987-ff7c-492f-83fb-ffc6a10b273d]
[2019-03-08 16:39:02,145: INFO/MainProcess] Task rackraj.tasks.QueuedJobRun[1db6e987-ff7c-492f-83fb-ffc6a10b273d] succeeded in 0.0196631990002s: None
[2019-03-08 16:40:02,123: INFO/MainProcess] Received task: rackraj.tasks.QueuedJobRun[09c907f3-de67-4468-b3f1-a0aeb545bca3]
[2019-03-08 16:40:02,145: INFO/MainProcess] Task rackraj.tasks.QueuedJobRun[09c907f3-de67-4468-b3f1-a0aeb545bca3] succeeded in 0.0193974319991s: None
[2019-03-08 16:41:02,101: INFO/MainProcess] Received task: rackraj.tasks.QueuedJobRun[cd60668b-f7fa-4a5a-9e6b-d200bfdfc9ec]
[2019-03-08 16:41:02,123: INFO/MainProcess] Task rackraj.tasks.QueuedJobRun[cd60668b-f7fa-4a5a-9e6b-d200bfdfc9ec] succeeded in 0.0196034559995s: None
[2019-03-08 16:42:02,060: INFO/MainProcess] Received task: rackraj.tasks.QueuedJobRun[c23eede5-51bf-44fe-9f82-941268de959d]
[2019-03-08 16:42:02,087: INFO/MainProcess] Task rackraj.tasks.QueuedJobRun[c23eede5-51bf-44fe-9f82-941268de959d] succeeded in 0.0230828179992s: None
[2019-03-08 16:43:02,062: INFO/MainProcess] Received task: rackraj.tasks.QueuedJobRun[c6515de1-a4d2-4e8e-93cb-3e2af95f5a55]
[2019-03-08 16:44:02,064: INFO/MainProcess] Received task: rackraj.tasks.QueuedJobRun[219dd97b-b005-4b38-9c91-efbbcc305073]
[2019-03-08 16:44:02,090: INFO/MainProcess] Task rackraj.tasks.QueuedJobRun[219dd97b-b005-4b38-9c91-efbbcc305073] succeeded in 0.0210686099999s: None
[2019-03-08 16:45:02,070: INFO/MainProcess] Received task: rackraj.tasks.QueuedJobRun[fdc8fe29-d940-485d-bbf1-73c589902367]
[2019-03-08 16:45:02,093: INFO/MainProcess] Task rackraj.tasks.QueuedJobRun[fdc8fe29-d940-485d-bbf1-73c589902367] succeeded in 0.0184048100018s: None
[2019-03-08 16:45:39,863: INFO/MainProcess] Task rackraj.tasks.QueuedJobRun[c6515de1-a4d2-4e8e-93cb-3e2af95f5a55] succeeded in 157.798872653s: None
[2019-03-08 16:46:02,066: INFO/MainProcess] Received task: rackraj.tasks.QueuedJobRun[838b30d3-9dd7-4cdc-b741-469a2e3f81e0]
[2019-03-08 16:46:02,097: INFO/MainProcess] Task rackraj.tasks.QueuedJobRun[838b30d3-9dd7-4cdc-b741-469a2e3f81e0] succeeded in 0.028842148s: None
[2019-03-08 16:47:02,099: INFO/MainProcess] Received task: rackraj.tasks.QueuedJobRun[d26bda10-398c-477f-9340-ec10cd009378]
[2019-03-08 16:47:02,122: INFO/MainProcess] Task rackraj.tasks.QueuedJobRun[d26bda10-398c-477f-9340-ec10cd009378] succeeded in 0.0196508899971s: None
[2019-03-08 16:48:02,120: INFO/MainProcess] Received task: rackraj.tasks.QueuedJobRun[2aa42f6d-db24-4f84-ae23-7a43ad9ed305]
[2019-03-08 16:48:02,140: INFO/MainProcess] Task rackraj.tasks.QueuedJobRun[2aa42f6d-db24-4f84-ae23-7a43ad9ed305] succeeded in 0.0178794210005s: None
[2019-03-08 16:49:02,119: INFO/MainProcess] Received task: rackraj.tasks.QueuedJobRun[d1f469d6-2149-4784-b832-96e2319ab324]
[2019-03-08 16:49:02,151: INFO/MainProcess] Task rackraj.tasks.QueuedJobRun[d1f469d6-2149-4784-b832-96e2319ab324] succeeded in 0.0290069399998s: None
[2019-03-08 16:50:02,067: INFO/MainProcess] Received task: rackraj.tasks.QueuedJobRun[ab484374-76e3-4410-878e-68622d7d4a96]
[2019-03-08 16:50:02,087: INFO/MainProcess] Task rackraj.tasks.QueuedJobRun[ab484374-76e3-4410-878e-68622d7d4a96] succeeded in 0.0175144820023s: None
[2019-03-08 16:51:02,112: INFO/MainProcess] Received task: rackraj.tasks.QueuedJobRun[702dc35f-7f94-4e8e-8d3d-f3559ea265d8]
[2019-03-08 16:51:02,136: INFO/MainProcess] Task rackraj.tasks.QueuedJobRun[702dc35f-7f94-4e8e-8d3d-f3559ea265d8] succeeded in 0.0212717620016s: None
[2019-03-08 16:52:02,075: INFO/MainProcess] Received task: rackraj.tasks.QueuedJobRun[0ac48c4a-bcca-4a35-af6e-b52eb3ac2097]
[2019-03-08 16:52:02,097: INFO/MainProcess] Task rackraj.tasks.QueuedJobRun[0ac48c4a-bcca-4a35-af6e-b52eb3ac2097] succeeded in 0.0189804369984s: None
[2019-03-08 16:53:02,065: INFO/MainProcess] Received task: rackraj.tasks.QueuedJobRun[51cf8b96-304f-4a4a-87f0-6355fbec88c2]
[2019-03-08 16:53:02,088: INFO/MainProcess] Task rackraj.tasks.QueuedJobRun[51cf8b96-304f-4a4a-87f0-6355fbec88c2] succeeded in 0.0204826970003s: None
[2019-03-08 16:54:02,076: INFO/MainProcess] Received task: rackraj.tasks.QueuedJobRun[8063a331-f64a-479d-9edc-ae8cd9716981]
[2019-03-08 16:54:02,099: INFO/MainProcess] Task rackraj.tasks.QueuedJobRun[8063a331-f64a-479d-9edc-ae8cd9716981] succeeded in 0.0206404870005s: None
[2019-03-08 16:55:02,060: INFO/MainProcess] Received task: rackraj.tasks.QueuedJobRun[88125fb1-69e4-46f5-af69-ee252e0686d0]
[2019-03-08 16:55:02,082: INFO/MainProcess] Task rackraj.tasks.QueuedJobRun[88125fb1-69e4-46f5-af69-ee252e0686d0] succeeded in 0.0194035110035s: None
[2019-03-08 16:56:02,114: INFO/MainProcess] Received task: rackraj.tasks.QueuedJobRun[578e92f4-3eed-4c19-8417-e4c794e92691]
[2019-03-08 16:56:02,137: INFO/MainProcess] Task rackraj.tasks.QueuedJobRun[578e92f4-3eed-4c19-8417-e4c794e92691] succeeded in 0.0201275810032s: None
[2019-03-08 16:57:02,061: INFO/MainProcess] Received task: rackraj.tasks.QueuedJobRun[b5d42883-dcdf-42bc-a452-937c85c6c52a]
[2019-03-08 16:57:02,089: INFO/MainProcess] Task rackraj.tasks.QueuedJobRun[b5d42883-dcdf-42bc-a452-937c85c6c52a] succeeded in 0.0257493969984s: None
[2019-03-08 16:58:02,066: INFO/MainProcess] Received task: rackraj.tasks.QueuedJobRun[819b5735-2990-45fa-b3c4-503e86ac06b6]
[2019-03-08 16:58:06,294: INFO/MainProcess] Task rackraj.tasks.QueuedJobRun[819b5735-2990-45fa-b3c4-503e86ac06b6] succeeded in 4.224289872s: None
[2019-03-08 16:59:02,110: INFO/MainProcess] Received task: rackraj.tasks.QueuedJobRun[c058447f-6b43-4bff-af05-17e8082fdc8f]
[2019-03-08 16:59:12,849: INFO/MainProcess] Task rackraj.tasks.QueuedJobRun[c058447f-6b43-4bff-af05-17e8082fdc8f] succeeded in 10.735686682s: None
[2019-03-08 17:00:02,078: INFO/MainProcess] Received task: rackraj.tasks.QueuedJobRun[8d695a7b-c8b2-4591-be4a-85c84ba128a1]
[2019-03-08 17:00:14,998: INFO/MainProcess] Task rackraj.tasks.QueuedJobRun[8d695a7b-c8b2-4591-be4a-85c84ba128a1] succeeded in 12.917033781s: None
[2019-03-08 17:01:02,077: INFO/MainProcess] Received task: rackraj.tasks.QueuedJobRun[1c7eebc1-2cc5-4563-8987-e018bd8c3fbb]
[2019-03-08 17:01:15,791: INFO/MainProcess] Task rackraj.tasks.QueuedJobRun[1c7eebc1-2cc5-4563-8987-e018bd8c3fbb] succeeded in 13.711104642s: None
[2019-03-08 17:02:02,072: INFO/MainProcess] Received task: rackraj.tasks.QueuedJobRun[a01a749f-0dd1-490d-9d5c-9b21c8740d03]
[2019-03-08 17:02:03,576: INFO/MainProcess] Task rackraj.tasks.QueuedJobRun[a01a749f-0dd1-490d-9d5c-9b21c8740d03] succeeded in 1.501416259s: None
[2019-03-08 17:03:02,110: INFO/MainProcess] Received task: rackraj.tasks.QueuedJobRun[b063aaf0-0749-47ef-a997-5427426f6941]
[2019-03-08 17:03:06,686: INFO/MainProcess] Task rackraj.tasks.QueuedJobRun[b063aaf0-0749-47ef-a997-5427426f6941] succeeded in 4.574215794s: None
[2019-03-08 17:04:02,067: INFO/MainProcess] Received task: rackraj.tasks.QueuedJobRun[82996502-94c0-4699-9931-6cf446b7bb0c]
[2019-03-08 17:04:02,091: INFO/MainProcess] Task rackraj.tasks.QueuedJobRun[82996502-94c0-4699-9931-6cf446b7bb0c] succeeded in 0.0198070580009s: None
[2019-03-08 17:05:02,075: INFO/MainProcess] Received task: rackraj.tasks.QueuedJobRun[5c2472c7-3c7c-4f95-972f-d22f4235f0a7]
[2019-03-08 17:05:10,129: INFO/MainProcess] Task rackraj.tasks.QueuedJobRun[5c2472c7-3c7c-4f95-972f-d22f4235f0a7] succeeded in 8.049939895s: None
[2019-03-08 17:06:02,122: INFO/MainProcess] Received task: rackraj.tasks.QueuedJobRun[9ea5f97f-ceab-4c7d-87ac-c71080e9937e]
[2019-03-08 17:06:05,521: INFO/MainProcess] Task rackraj.tasks.QueuedJobRun[9ea5f97f-ceab-4c7d-87ac-c71080e9937e] succeeded in 3.396752595s: None
[2019-03-08 17:07:02,069: INFO/MainProcess] Received task: rackraj.tasks.QueuedJobRun[088c40e8-f09d-4722-ad41-7c73c700268f]
[2019-03-08 17:07:02,091: INFO/MainProcess] Task rackraj.tasks.QueuedJobRun[088c40e8-f09d-4722-ad41-7c73c700268f] succeeded in 0.018971149002s: None
[2019-03-08 17:08:02,123: INFO/MainProcess] Received task: rackraj.tasks.QueuedJobRun[41c47964-6cf8-419e-a023-ae9640e5efa3]
[2019-03-08 17:08:02,145: INFO/MainProcess] Task rackraj.tasks.QueuedJobRun[41c47964-6cf8-419e-a023-ae9640e5efa3] succeeded in 0.0191210939993s: None
[2019-03-08 17:09:02,122: INFO/MainProcess] Received task: rackraj.tasks.QueuedJobRun[9579d8b4-4e52-4499-9689-88714d166020]
[2019-03-08 17:09:02,147: INFO/MainProcess] Task rackraj.tasks.QueuedJobRun[9579d8b4-4e52-4499-9689-88714d166020] succeeded in 0.0215788040005s: None
[2019-03-08 17:10:02,128: INFO/MainProcess] Received task: rackraj.tasks.QueuedJobRun[b08fcb49-1385-43bb-9707-51564eac68cf]
[2019-03-08 17:10:02,151: INFO/MainProcess] Task rackraj.tasks.QueuedJobRun[b08fcb49-1385-43bb-9707-51564eac68cf] succeeded in 0.0193106879997s: None
[2019-03-08 17:11:02,070: INFO/MainProcess] Received task: rackraj.tasks.QueuedJobRun[1b2bb954-96f9-4a14-a3fc-bfbccc9e181d]
[2019-03-08 17:11:02,095: INFO/MainProcess] Task rackraj.tasks.QueuedJobRun[1b2bb954-96f9-4a14-a3fc-bfbccc9e181d] succeeded in 0.0219785209993s: None
[2019-03-08 17:12:02,092: INFO/MainProcess] Received task: rackraj.tasks.QueuedJobRun[306a3dc2-f703-4b1d-bdec-6b883f1e3269]
[2019-03-08 17:12:02,120: INFO/MainProcess] Task rackraj.tasks.QueuedJobRun[306a3dc2-f703-4b1d-bdec-6b883f1e3269] succeeded in 0.0221758209991s: None
[2019-03-08 10:59:52,175: WARNING/Worker-16] {u'discovered_service': u'PServer.exe', u'remote_port_time': u'2019-03-08 02:45:03', u'listening_ip': u'11.11.211.82', u'discovered_service_display_name': u'D:\\PServer.exe ', u'remote_ips': u'11.11.225.74:(47994)', u'port': 2101, 'device_id': 598}